2021-07-08 00:31:32,033 root  INFO   49 15892 MainThread 15888 C:\Users\OneDrive - ncist.edu.cn\project\mystock\logger\my_logger.py a start
2021-07-08 00:31:32,033 root  INFO   51 15892 MainThread 15888 C:\Users\OneDrive - ncist.edu.cn\project\mystock\logger\my_logger.py a finshed
2021-07-08 00:31:37,096 root  INFO   49 17728 Thread-1 15888 C:\Users\OneDrive - ncist.edu.cn\project\mystock\data\akshare\yjbb.py update_yjbb_to_db start
2021-07-08 00:31:37,097 root  INFO   49 17756 Thread-2 15888 C:\Users\OneDrive - ncist.edu.cn\project\mystock\data\akshare\north_net_flow.py save_north_data start
2021-07-08 00:31:37,349 root  ERROR   54 17756 Thread-2 15888 C:\Users\OneDrive - ncist.edu.cn\project\mystock\data\akshare\north_net_flow.py save_north_data error
2021-07-08 00:31:37,349 root  ERROR   55 17756 Thread-2 15888 Traceback (most recent call last):
  File "C:\Program Files\python37\lib\site-packages\pymysql\connections.py", line 571, in connect
    **kwargs)
  File "C:\Program Files\python37\lib\socket.py", line 707, in create_connection
    for res in getaddrinfo(host, port, 0, SOCK_STREAM):
  File "C:\Program Files\python37\lib\socket.py", line 752, in getaddrinfo
    for res in _socket.getaddrinfo(host, port, family, type, proto, flags):
socket.gaierror: [Errno 11001] getaddrinfo failed

During handling of the above exception, another exception occurred:

Traceback (most recent call last):
  File "C:\Program Files\python37\lib\site-packages\sqlalchemy\engine\base.py", line 2336, in _wrap_pool_connect
    return fn()
  File "C:\Program Files\python37\lib\site-packages\sqlalchemy\pool\base.py", line 364, in connect
    return _ConnectionFairy._checkout(self)
  File "C:\Program Files\python37\lib\site-packages\sqlalchemy\pool\base.py", line 778, in _checkout
    fairy = _ConnectionRecord.checkout(pool)
  File "C:\Program Files\python37\lib\site-packages\sqlalchemy\pool\base.py", line 495, in checkout
    rec = pool._do_get()
  File "C:\Program Files\python37\lib\site-packages\sqlalchemy\pool\impl.py", line 140, in _do_get
    self._dec_overflow()
  File "C:\Program Files\python37\lib\site-packages\sqlalchemy\util\langhelpers.py", line 70, in __exit__
    with_traceback=exc_tb,
  File "C:\Program Files\python37\lib\site-packages\sqlalchemy\util\compat.py", line 182, in raise_
    raise exception
  File "C:\Program Files\python37\lib\site-packages\sqlalchemy\pool\impl.py", line 137, in _do_get
    return self._create_connection()
  File "C:\Program Files\python37\lib\site-packages\sqlalchemy\pool\base.py", line 309, in _create_connection
    return _ConnectionRecord(self)
  File "C:\Program Files\python37\lib\site-packages\sqlalchemy\pool\base.py", line 440, in __init__
    self.__connect(first_connect_check=True)
  File "C:\Program Files\python37\lib\site-packages\sqlalchemy\pool\base.py", line 661, in __connect
    pool.logger.debug("Error on connect(): %s", e)
  File "C:\Program Files\python37\lib\site-packages\sqlalchemy\util\langhelpers.py", line 70, in __exit__
    with_traceback=exc_tb,
  File "C:\Program Files\python37\lib\site-packages\sqlalchemy\util\compat.py", line 182, in raise_
    raise exception
  File "C:\Program Files\python37\lib\site-packages\sqlalchemy\pool\base.py", line 656, in __connect
    connection = pool._invoke_creator(self)
  File "C:\Program Files\python37\lib\site-packages\sqlalchemy\engine\strategies.py", line 114, in connect
    return dialect.connect(*cargs, **cparams)
  File "C:\Program Files\python37\lib\site-packages\sqlalchemy\engine\default.py", line 493, in connect
    return self.dbapi.connect(*cargs, **cparams)
  File "C:\Program Files\python37\lib\site-packages\pymysql\__init__.py", line 94, in Connect
    return Connection(*args, **kwargs)
  File "C:\Program Files\python37\lib\site-packages\pymysql\connections.py", line 327, in __init__
    self.connect()
  File "C:\Program Files\python37\lib\site-packages\pymysql\connections.py", line 619, in connect
    raise exc
pymysql.err.OperationalError: (2003, "Can't connect to MySQL server on 'qq532978773.f3322.net' ([Errno 11001] getaddrinfo failed)")

The above exception was the direct cause of the following exception:

Traceback (most recent call last):
  File "C:\Users\OneDrive - ncist.edu.cn\project\mystock\logger\my_logger.py", line 50, in wrapped_function
    res=func(*args, **kwargs)
  File "C:\Users\OneDrive - ncist.edu.cn\project\mystock\data\akshare\north_net_flow.py", line 160, in save_north_data
    utils.timeUtil.saveOperationTime(hold_stock_table)
  File "C:\Users\OneDrive - ncist.edu.cn\project\mystock\utils\timeUtil.py", line 29, in saveOperationTime
    operation.to_sql(name='tb_operation_time',con=con,if_exists='append',index=False)
  File "C:\Program Files\python37\lib\site-packages\pandas\core\generic.py", line 2879, in to_sql
    method=method,
  File "C:\Program Files\python37\lib\site-packages\pandas\io\sql.py", line 728, in to_sql
    **engine_kwargs,
  File "C:\Program Files\python37\lib\site-packages\pandas\io\sql.py", line 1758, in to_sql
    dtype=dtype,
  File "C:\Program Files\python37\lib\site-packages\pandas\io\sql.py", line 1650, in prep_table
    table.create()
  File "C:\Program Files\python37\lib\site-packages\pandas\io\sql.py", line 856, in create
    if self.exists():
  File "C:\Program Files\python37\lib\site-packages\pandas\io\sql.py", line 840, in exists
    return self.pd_sql.has_table(self.name, self.schema)
  File "C:\Program Files\python37\lib\site-packages\pandas\io\sql.py", line 1787, in has_table
    self.connectable.dialect.has_table, name, schema or self.meta.schema
  File "C:\Program Files\python37\lib\site-packages\sqlalchemy\engine\base.py", line 2211, in run_callable
    with self._contextual_connect() as conn:
  File "C:\Program Files\python37\lib\site-packages\sqlalchemy\engine\base.py", line 2302, in _contextual_connect
    self._wrap_pool_connect(self.pool.connect, None),
  File "C:\Program Files\python37\lib\site-packages\sqlalchemy\engine\base.py", line 2340, in _wrap_pool_connect
    e, dialect, self
  File "C:\Program Files\python37\lib\site-packages\sqlalchemy\engine\base.py", line 1584, in _handle_dbapi_exception_noconnection
    sqlalchemy_exception, with_traceback=exc_info[2], from_=e
  File "C:\Program Files\python37\lib\site-packages\sqlalchemy\util\compat.py", line 182, in raise_
    raise exception
  File "C:\Program Files\python37\lib\site-packages\sqlalchemy\engine\base.py", line 2336, in _wrap_pool_connect
    return fn()
  File "C:\Program Files\python37\lib\site-packages\sqlalchemy\pool\base.py", line 364, in connect
    return _ConnectionFairy._checkout(self)
  File "C:\Program Files\python37\lib\site-packages\sqlalchemy\pool\base.py", line 778, in _checkout
    fairy = _ConnectionRecord.checkout(pool)
  File "C:\Program Files\python37\lib\site-packages\sqlalchemy\pool\base.py", line 495, in checkout
    rec = pool._do_get()
  File "C:\Program Files\python37\lib\site-packages\sqlalchemy\pool\impl.py", line 140, in _do_get
    self._dec_overflow()
  File "C:\Program Files\python37\lib\site-packages\sqlalchemy\util\langhelpers.py", line 70, in __exit__
    with_traceback=exc_tb,
  File "C:\Program Files\python37\lib\site-packages\sqlalchemy\util\compat.py", line 182, in raise_
    raise exception
  File "C:\Program Files\python37\lib\site-packages\sqlalchemy\pool\impl.py", line 137, in _do_get
    return self._create_connection()
  File "C:\Program Files\python37\lib\site-packages\sqlalchemy\pool\base.py", line 309, in _create_connection
    return _ConnectionRecord(self)
  File "C:\Program Files\python37\lib\site-packages\sqlalchemy\pool\base.py", line 440, in __init__
    self.__connect(first_connect_check=True)
  File "C:\Program Files\python37\lib\site-packages\sqlalchemy\pool\base.py", line 661, in __connect
    pool.logger.debug("Error on connect(): %s", e)
  File "C:\Program Files\python37\lib\site-packages\sqlalchemy\util\langhelpers.py", line 70, in __exit__
    with_traceback=exc_tb,
  File "C:\Program Files\python37\lib\site-packages\sqlalchemy\util\compat.py", line 182, in raise_
    raise exception
  File "C:\Program Files\python37\lib\site-packages\sqlalchemy\pool\base.py", line 656, in __connect
    connection = pool._invoke_creator(self)
  File "C:\Program Files\python37\lib\site-packages\sqlalchemy\engine\strategies.py", line 114, in connect
    return dialect.connect(*cargs, **cparams)
  File "C:\Program Files\python37\lib\site-packages\sqlalchemy\engine\default.py", line 493, in connect
    return self.dbapi.connect(*cargs, **cparams)
  File "C:\Program Files\python37\lib\site-packages\pymysql\__init__.py", line 94, in Connect
    return Connection(*args, **kwargs)
  File "C:\Program Files\python37\lib\site-packages\pymysql\connections.py", line 327, in __init__
    self.connect()
  File "C:\Program Files\python37\lib\site-packages\pymysql\connections.py", line 619, in connect
    raise exc
sqlalchemy.exc.OperationalError: (pymysql.err.OperationalError) (2003, "Can't connect to MySQL server on 'qq532978773.f3322.net' ([Errno 11001] getaddrinfo failed)")
(Background on this error at: http://sqlalche.me/e/13/e3q8)

2021-07-08 00:31:37,484 root  ERROR   54 17728 Thread-1 15888 C:\Users\OneDrive - ncist.edu.cn\project\mystock\data\akshare\yjbb.py update_yjbb_to_db error
2021-07-08 00:31:37,484 root  ERROR   55 17728 Thread-1 15888 Traceback (most recent call last):
  File "C:\Program Files\python37\lib\site-packages\pymysql\connections.py", line 571, in connect
    **kwargs)
  File "C:\Program Files\python37\lib\socket.py", line 707, in create_connection
    for res in getaddrinfo(host, port, 0, SOCK_STREAM):
  File "C:\Program Files\python37\lib\socket.py", line 752, in getaddrinfo
    for res in _socket.getaddrinfo(host, port, family, type, proto, flags):
socket.gaierror: [Errno 11001] getaddrinfo failed

During handling of the above exception, another exception occurred:

Traceback (most recent call last):
  File "C:\Program Files\python37\lib\site-packages\sqlalchemy\engine\base.py", line 2336, in _wrap_pool_connect
    return fn()
  File "C:\Program Files\python37\lib\site-packages\sqlalchemy\pool\base.py", line 364, in connect
    return _ConnectionFairy._checkout(self)
  File "C:\Program Files\python37\lib\site-packages\sqlalchemy\pool\base.py", line 778, in _checkout
    fairy = _ConnectionRecord.checkout(pool)
  File "C:\Program Files\python37\lib\site-packages\sqlalchemy\pool\base.py", line 495, in checkout
    rec = pool._do_get()
  File "C:\Program Files\python37\lib\site-packages\sqlalchemy\pool\impl.py", line 140, in _do_get
    self._dec_overflow()
  File "C:\Program Files\python37\lib\site-packages\sqlalchemy\util\langhelpers.py", line 70, in __exit__
    with_traceback=exc_tb,
  File "C:\Program Files\python37\lib\site-packages\sqlalchemy\util\compat.py", line 182, in raise_
    raise exception
  File "C:\Program Files\python37\lib\site-packages\sqlalchemy\pool\impl.py", line 137, in _do_get
    return self._create_connection()
  File "C:\Program Files\python37\lib\site-packages\sqlalchemy\pool\base.py", line 309, in _create_connection
    return _ConnectionRecord(self)
  File "C:\Program Files\python37\lib\site-packages\sqlalchemy\pool\base.py", line 440, in __init__
    self.__connect(first_connect_check=True)
  File "C:\Program Files\python37\lib\site-packages\sqlalchemy\pool\base.py", line 661, in __connect
    pool.logger.debug("Error on connect(): %s", e)
  File "C:\Program Files\python37\lib\site-packages\sqlalchemy\util\langhelpers.py", line 70, in __exit__
    with_traceback=exc_tb,
  File "C:\Program Files\python37\lib\site-packages\sqlalchemy\util\compat.py", line 182, in raise_
    raise exception
  File "C:\Program Files\python37\lib\site-packages\sqlalchemy\pool\base.py", line 656, in __connect
    connection = pool._invoke_creator(self)
  File "C:\Program Files\python37\lib\site-packages\sqlalchemy\engine\strategies.py", line 114, in connect
    return dialect.connect(*cargs, **cparams)
  File "C:\Program Files\python37\lib\site-packages\sqlalchemy\engine\default.py", line 493, in connect
    return self.dbapi.connect(*cargs, **cparams)
  File "C:\Program Files\python37\lib\site-packages\pymysql\__init__.py", line 94, in Connect
    return Connection(*args, **kwargs)
  File "C:\Program Files\python37\lib\site-packages\pymysql\connections.py", line 327, in __init__
    self.connect()
  File "C:\Program Files\python37\lib\site-packages\pymysql\connections.py", line 619, in connect
    raise exc
pymysql.err.OperationalError: (2003, "Can't connect to MySQL server on 'qq532978773.f3322.net' ([Errno 11001] getaddrinfo failed)")

The above exception was the direct cause of the following exception:

Traceback (most recent call last):
  File "C:\Users\OneDrive - ncist.edu.cn\project\mystock\logger\my_logger.py", line 50, in wrapped_function
    res=func(*args, **kwargs)
  File "C:\Users\OneDrive - ncist.edu.cn\project\mystock\data\akshare\yjbb.py", line 109, in update_yjbb_to_db
    timeUtil.saveOperationTime(tablename)
  File "C:\Users\OneDrive - ncist.edu.cn\project\mystock\utils\timeUtil.py", line 29, in saveOperationTime
    operation.to_sql(name='tb_operation_time',con=con,if_exists='append',index=False)
  File "C:\Program Files\python37\lib\site-packages\pandas\core\generic.py", line 2879, in to_sql
    method=method,
  File "C:\Program Files\python37\lib\site-packages\pandas\io\sql.py", line 728, in to_sql
    **engine_kwargs,
  File "C:\Program Files\python37\lib\site-packages\pandas\io\sql.py", line 1758, in to_sql
    dtype=dtype,
  File "C:\Program Files\python37\lib\site-packages\pandas\io\sql.py", line 1650, in prep_table
    table.create()
  File "C:\Program Files\python37\lib\site-packages\pandas\io\sql.py", line 856, in create
    if self.exists():
  File "C:\Program Files\python37\lib\site-packages\pandas\io\sql.py", line 840, in exists
    return self.pd_sql.has_table(self.name, self.schema)
  File "C:\Program Files\python37\lib\site-packages\pandas\io\sql.py", line 1787, in has_table
    self.connectable.dialect.has_table, name, schema or self.meta.schema
  File "C:\Program Files\python37\lib\site-packages\sqlalchemy\engine\base.py", line 2211, in run_callable
    with self._contextual_connect() as conn:
  File "C:\Program Files\python37\lib\site-packages\sqlalchemy\engine\base.py", line 2302, in _contextual_connect
    self._wrap_pool_connect(self.pool.connect, None),
  File "C:\Program Files\python37\lib\site-packages\sqlalchemy\engine\base.py", line 2340, in _wrap_pool_connect
    e, dialect, self
  File "C:\Program Files\python37\lib\site-packages\sqlalchemy\engine\base.py", line 1584, in _handle_dbapi_exception_noconnection
    sqlalchemy_exception, with_traceback=exc_info[2], from_=e
  File "C:\Program Files\python37\lib\site-packages\sqlalchemy\util\compat.py", line 182, in raise_
    raise exception
  File "C:\Program Files\python37\lib\site-packages\sqlalchemy\engine\base.py", line 2336, in _wrap_pool_connect
    return fn()
  File "C:\Program Files\python37\lib\site-packages\sqlalchemy\pool\base.py", line 364, in connect
    return _ConnectionFairy._checkout(self)
  File "C:\Program Files\python37\lib\site-packages\sqlalchemy\pool\base.py", line 778, in _checkout
    fairy = _ConnectionRecord.checkout(pool)
  File "C:\Program Files\python37\lib\site-packages\sqlalchemy\pool\base.py", line 495, in checkout
    rec = pool._do_get()
  File "C:\Program Files\python37\lib\site-packages\sqlalchemy\pool\impl.py", line 140, in _do_get
    self._dec_overflow()
  File "C:\Program Files\python37\lib\site-packages\sqlalchemy\util\langhelpers.py", line 70, in __exit__
    with_traceback=exc_tb,
  File "C:\Program Files\python37\lib\site-packages\sqlalchemy\util\compat.py", line 182, in raise_
    raise exception
  File "C:\Program Files\python37\lib\site-packages\sqlalchemy\pool\impl.py", line 137, in _do_get
    return self._create_connection()
  File "C:\Program Files\python37\lib\site-packages\sqlalchemy\pool\base.py", line 309, in _create_connection
    return _ConnectionRecord(self)
  File "C:\Program Files\python37\lib\site-packages\sqlalchemy\pool\base.py", line 440, in __init__
    self.__connect(first_connect_check=True)
  File "C:\Program Files\python37\lib\site-packages\sqlalchemy\pool\base.py", line 661, in __connect
    pool.logger.debug("Error on connect(): %s", e)
  File "C:\Program Files\python37\lib\site-packages\sqlalchemy\util\langhelpers.py", line 70, in __exit__
    with_traceback=exc_tb,
  File "C:\Program Files\python37\lib\site-packages\sqlalchemy\util\compat.py", line 182, in raise_
    raise exception
  File "C:\Program Files\python37\lib\site-packages\sqlalchemy\pool\base.py", line 656, in __connect
    connection = pool._invoke_creator(self)
  File "C:\Program Files\python37\lib\site-packages\sqlalchemy\engine\strategies.py", line 114, in connect
    return dialect.connect(*cargs, **cparams)
  File "C:\Program Files\python37\lib\site-packages\sqlalchemy\engine\default.py", line 493, in connect
    return self.dbapi.connect(*cargs, **cparams)
  File "C:\Program Files\python37\lib\site-packages\pymysql\__init__.py", line 94, in Connect
    return Connection(*args, **kwargs)
  File "C:\Program Files\python37\lib\site-packages\pymysql\connections.py", line 327, in __init__
    self.connect()
  File "C:\Program Files\python37\lib\site-packages\pymysql\connections.py", line 619, in connect
    raise exc
sqlalchemy.exc.OperationalError: (pymysql.err.OperationalError) (2003, "Can't connect to MySQL server on 'qq532978773.f3322.net' ([Errno 11001] getaddrinfo failed)")
(Background on this error at: http://sqlalche.me/e/13/e3q8)

2021-07-08 00:31:37,485 root  INFO   49 17728 Thread-1 15888 C:\Users\OneDrive - ncist.edu.cn\project\mystock\data\akshare\yjbb.py update_yjbb_to_db start
2021-07-08 00:31:37,681 root  ERROR   54 17728 Thread-1 15888 C:\Users\OneDrive - ncist.edu.cn\project\mystock\data\akshare\yjbb.py update_yjbb_to_db error
2021-07-08 00:31:37,681 root  ERROR   55 17728 Thread-1 15888 Traceback (most recent call last):
  File "C:\Program Files\python37\lib\site-packages\pymysql\connections.py", line 571, in connect
    **kwargs)
  File "C:\Program Files\python37\lib\socket.py", line 707, in create_connection
    for res in getaddrinfo(host, port, 0, SOCK_STREAM):
  File "C:\Program Files\python37\lib\socket.py", line 752, in getaddrinfo
    for res in _socket.getaddrinfo(host, port, family, type, proto, flags):
socket.gaierror: [Errno 11001] getaddrinfo failed

During handling of the above exception, another exception occurred:

Traceback (most recent call last):
  File "C:\Program Files\python37\lib\site-packages\sqlalchemy\engine\base.py", line 2336, in _wrap_pool_connect
    return fn()
  File "C:\Program Files\python37\lib\site-packages\sqlalchemy\pool\base.py", line 364, in connect
    return _ConnectionFairy._checkout(self)
  File "C:\Program Files\python37\lib\site-packages\sqlalchemy\pool\base.py", line 778, in _checkout
    fairy = _ConnectionRecord.checkout(pool)
  File "C:\Program Files\python37\lib\site-packages\sqlalchemy\pool\base.py", line 495, in checkout
    rec = pool._do_get()
  File "C:\Program Files\python37\lib\site-packages\sqlalchemy\pool\impl.py", line 140, in _do_get
    self._dec_overflow()
  File "C:\Program Files\python37\lib\site-packages\sqlalchemy\util\langhelpers.py", line 70, in __exit__
    with_traceback=exc_tb,
  File "C:\Program Files\python37\lib\site-packages\sqlalchemy\util\compat.py", line 182, in raise_
    raise exception
  File "C:\Program Files\python37\lib\site-packages\sqlalchemy\pool\impl.py", line 137, in _do_get
    return self._create_connection()
  File "C:\Program Files\python37\lib\site-packages\sqlalchemy\pool\base.py", line 309, in _create_connection
    return _ConnectionRecord(self)
  File "C:\Program Files\python37\lib\site-packages\sqlalchemy\pool\base.py", line 440, in __init__
    self.__connect(first_connect_check=True)
  File "C:\Program Files\python37\lib\site-packages\sqlalchemy\pool\base.py", line 661, in __connect
    pool.logger.debug("Error on connect(): %s", e)
  File "C:\Program Files\python37\lib\site-packages\sqlalchemy\util\langhelpers.py", line 70, in __exit__
    with_traceback=exc_tb,
  File "C:\Program Files\python37\lib\site-packages\sqlalchemy\util\compat.py", line 182, in raise_
    raise exception
  File "C:\Program Files\python37\lib\site-packages\sqlalchemy\pool\base.py", line 656, in __connect
    connection = pool._invoke_creator(self)
  File "C:\Program Files\python37\lib\site-packages\sqlalchemy\engine\strategies.py", line 114, in connect
    return dialect.connect(*cargs, **cparams)
  File "C:\Program Files\python37\lib\site-packages\sqlalchemy\engine\default.py", line 493, in connect
    return self.dbapi.connect(*cargs, **cparams)
  File "C:\Program Files\python37\lib\site-packages\pymysql\__init__.py", line 94, in Connect
    return Connection(*args, **kwargs)
  File "C:\Program Files\python37\lib\site-packages\pymysql\connections.py", line 327, in __init__
    self.connect()
  File "C:\Program Files\python37\lib\site-packages\pymysql\connections.py", line 619, in connect
    raise exc
pymysql.err.OperationalError: (2003, "Can't connect to MySQL server on 'qq532978773.f3322.net' ([Errno 11001] getaddrinfo failed)")

The above exception was the direct cause of the following exception:

Traceback (most recent call last):
  File "C:\Users\OneDrive - ncist.edu.cn\project\mystock\logger\my_logger.py", line 50, in wrapped_function
    res=func(*args, **kwargs)
  File "C:\Users\OneDrive - ncist.edu.cn\project\mystock\data\akshare\yjbb.py", line 109, in update_yjbb_to_db
    timeUtil.saveOperationTime(tablename)
  File "C:\Users\OneDrive - ncist.edu.cn\project\mystock\utils\timeUtil.py", line 29, in saveOperationTime
    operation.to_sql(name='tb_operation_time',con=con,if_exists='append',index=False)
  File "C:\Program Files\python37\lib\site-packages\pandas\core\generic.py", line 2879, in to_sql
    method=method,
  File "C:\Program Files\python37\lib\site-packages\pandas\io\sql.py", line 728, in to_sql
    **engine_kwargs,
  File "C:\Program Files\python37\lib\site-packages\pandas\io\sql.py", line 1758, in to_sql
    dtype=dtype,
  File "C:\Program Files\python37\lib\site-packages\pandas\io\sql.py", line 1650, in prep_table
    table.create()
  File "C:\Program Files\python37\lib\site-packages\pandas\io\sql.py", line 856, in create
    if self.exists():
  File "C:\Program Files\python37\lib\site-packages\pandas\io\sql.py", line 840, in exists
    return self.pd_sql.has_table(self.name, self.schema)
  File "C:\Program Files\python37\lib\site-packages\pandas\io\sql.py", line 1787, in has_table
    self.connectable.dialect.has_table, name, schema or self.meta.schema
  File "C:\Program Files\python37\lib\site-packages\sqlalchemy\engine\base.py", line 2211, in run_callable
    with self._contextual_connect() as conn:
  File "C:\Program Files\python37\lib\site-packages\sqlalchemy\engine\base.py", line 2302, in _contextual_connect
    self._wrap_pool_connect(self.pool.connect, None),
  File "C:\Program Files\python37\lib\site-packages\sqlalchemy\engine\base.py", line 2340, in _wrap_pool_connect
    e, dialect, self
  File "C:\Program Files\python37\lib\site-packages\sqlalchemy\engine\base.py", line 1584, in _handle_dbapi_exception_noconnection
    sqlalchemy_exception, with_traceback=exc_info[2], from_=e
  File "C:\Program Files\python37\lib\site-packages\sqlalchemy\util\compat.py", line 182, in raise_
    raise exception
  File "C:\Program Files\python37\lib\site-packages\sqlalchemy\engine\base.py", line 2336, in _wrap_pool_connect
    return fn()
  File "C:\Program Files\python37\lib\site-packages\sqlalchemy\pool\base.py", line 364, in connect
    return _ConnectionFairy._checkout(self)
  File "C:\Program Files\python37\lib\site-packages\sqlalchemy\pool\base.py", line 778, in _checkout
    fairy = _ConnectionRecord.checkout(pool)
  File "C:\Program Files\python37\lib\site-packages\sqlalchemy\pool\base.py", line 495, in checkout
    rec = pool._do_get()
  File "C:\Program Files\python37\lib\site-packages\sqlalchemy\pool\impl.py", line 140, in _do_get
    self._dec_overflow()
  File "C:\Program Files\python37\lib\site-packages\sqlalchemy\util\langhelpers.py", line 70, in __exit__
    with_traceback=exc_tb,
  File "C:\Program Files\python37\lib\site-packages\sqlalchemy\util\compat.py", line 182, in raise_
    raise exception
  File "C:\Program Files\python37\lib\site-packages\sqlalchemy\pool\impl.py", line 137, in _do_get
    return self._create_connection()
  File "C:\Program Files\python37\lib\site-packages\sqlalchemy\pool\base.py", line 309, in _create_connection
    return _ConnectionRecord(self)
  File "C:\Program Files\python37\lib\site-packages\sqlalchemy\pool\base.py", line 440, in __init__
    self.__connect(first_connect_check=True)
  File "C:\Program Files\python37\lib\site-packages\sqlalchemy\pool\base.py", line 661, in __connect
    pool.logger.debug("Error on connect(): %s", e)
  File "C:\Program Files\python37\lib\site-packages\sqlalchemy\util\langhelpers.py", line 70, in __exit__
    with_traceback=exc_tb,
  File "C:\Program Files\python37\lib\site-packages\sqlalchemy\util\compat.py", line 182, in raise_
    raise exception
  File "C:\Program Files\python37\lib\site-packages\sqlalchemy\pool\base.py", line 656, in __connect
    connection = pool._invoke_creator(self)
  File "C:\Program Files\python37\lib\site-packages\sqlalchemy\engine\strategies.py", line 114, in connect
    return dialect.connect(*cargs, **cparams)
  File "C:\Program Files\python37\lib\site-packages\sqlalchemy\engine\default.py", line 493, in connect
    return self.dbapi.connect(*cargs, **cparams)
  File "C:\Program Files\python37\lib\site-packages\pymysql\__init__.py", line 94, in Connect
    return Connection(*args, **kwargs)
  File "C:\Program Files\python37\lib\site-packages\pymysql\connections.py", line 327, in __init__
    self.connect()
  File "C:\Program Files\python37\lib\site-packages\pymysql\connections.py", line 619, in connect
    raise exc
sqlalchemy.exc.OperationalError: (pymysql.err.OperationalError) (2003, "Can't connect to MySQL server on 'qq532978773.f3322.net' ([Errno 11001] getaddrinfo failed)")
(Background on this error at: http://sqlalche.me/e/13/e3q8)

2021-07-08 00:31:37,682 root  INFO   49 17728 Thread-1 15888 C:\Users\OneDrive - ncist.edu.cn\project\mystock\data\akshare\yjbb.py update_yjbb_to_db start
2021-07-08 00:31:37,875 root  ERROR   54 17728 Thread-1 15888 C:\Users\OneDrive - ncist.edu.cn\project\mystock\data\akshare\yjbb.py update_yjbb_to_db error
2021-07-08 00:31:37,876 root  ERROR   55 17728 Thread-1 15888 Traceback (most recent call last):
  File "C:\Program Files\python37\lib\site-packages\pymysql\connections.py", line 571, in connect
    **kwargs)
  File "C:\Program Files\python37\lib\socket.py", line 707, in create_connection
    for res in getaddrinfo(host, port, 0, SOCK_STREAM):
  File "C:\Program Files\python37\lib\socket.py", line 752, in getaddrinfo
    for res in _socket.getaddrinfo(host, port, family, type, proto, flags):
socket.gaierror: [Errno 11001] getaddrinfo failed

During handling of the above exception, another exception occurred:

Traceback (most recent call last):
  File "C:\Program Files\python37\lib\site-packages\sqlalchemy\engine\base.py", line 2336, in _wrap_pool_connect
    return fn()
  File "C:\Program Files\python37\lib\site-packages\sqlalchemy\pool\base.py", line 364, in connect
    return _ConnectionFairy._checkout(self)
  File "C:\Program Files\python37\lib\site-packages\sqlalchemy\pool\base.py", line 778, in _checkout
    fairy = _ConnectionRecord.checkout(pool)
  File "C:\Program Files\python37\lib\site-packages\sqlalchemy\pool\base.py", line 495, in checkout
    rec = pool._do_get()
  File "C:\Program Files\python37\lib\site-packages\sqlalchemy\pool\impl.py", line 140, in _do_get
    self._dec_overflow()
  File "C:\Program Files\python37\lib\site-packages\sqlalchemy\util\langhelpers.py", line 70, in __exit__
    with_traceback=exc_tb,
  File "C:\Program Files\python37\lib\site-packages\sqlalchemy\util\compat.py", line 182, in raise_
    raise exception
  File "C:\Program Files\python37\lib\site-packages\sqlalchemy\pool\impl.py", line 137, in _do_get
    return self._create_connection()
  File "C:\Program Files\python37\lib\site-packages\sqlalchemy\pool\base.py", line 309, in _create_connection
    return _ConnectionRecord(self)
  File "C:\Program Files\python37\lib\site-packages\sqlalchemy\pool\base.py", line 440, in __init__
    self.__connect(first_connect_check=True)
  File "C:\Program Files\python37\lib\site-packages\sqlalchemy\pool\base.py", line 661, in __connect
    pool.logger.debug("Error on connect(): %s", e)
  File "C:\Program Files\python37\lib\site-packages\sqlalchemy\util\langhelpers.py", line 70, in __exit__
    with_traceback=exc_tb,
  File "C:\Program Files\python37\lib\site-packages\sqlalchemy\util\compat.py", line 182, in raise_
    raise exception
  File "C:\Program Files\python37\lib\site-packages\sqlalchemy\pool\base.py", line 656, in __connect
    connection = pool._invoke_creator(self)
  File "C:\Program Files\python37\lib\site-packages\sqlalchemy\engine\strategies.py", line 114, in connect
    return dialect.connect(*cargs, **cparams)
  File "C:\Program Files\python37\lib\site-packages\sqlalchemy\engine\default.py", line 493, in connect
    return self.dbapi.connect(*cargs, **cparams)
  File "C:\Program Files\python37\lib\site-packages\pymysql\__init__.py", line 94, in Connect
    return Connection(*args, **kwargs)
  File "C:\Program Files\python37\lib\site-packages\pymysql\connections.py", line 327, in __init__
    self.connect()
  File "C:\Program Files\python37\lib\site-packages\pymysql\connections.py", line 619, in connect
    raise exc
pymysql.err.OperationalError: (2003, "Can't connect to MySQL server on 'qq532978773.f3322.net' ([Errno 11001] getaddrinfo failed)")

The above exception was the direct cause of the following exception:

Traceback (most recent call last):
  File "C:\Users\OneDrive - ncist.edu.cn\project\mystock\logger\my_logger.py", line 50, in wrapped_function
    res=func(*args, **kwargs)
  File "C:\Users\OneDrive - ncist.edu.cn\project\mystock\data\akshare\yjbb.py", line 109, in update_yjbb_to_db
    timeUtil.saveOperationTime(tablename)
  File "C:\Users\OneDrive - ncist.edu.cn\project\mystock\utils\timeUtil.py", line 29, in saveOperationTime
    operation.to_sql(name='tb_operation_time',con=con,if_exists='append',index=False)
  File "C:\Program Files\python37\lib\site-packages\pandas\core\generic.py", line 2879, in to_sql
    method=method,
  File "C:\Program Files\python37\lib\site-packages\pandas\io\sql.py", line 728, in to_sql
    **engine_kwargs,
  File "C:\Program Files\python37\lib\site-packages\pandas\io\sql.py", line 1758, in to_sql
    dtype=dtype,
  File "C:\Program Files\python37\lib\site-packages\pandas\io\sql.py", line 1650, in prep_table
    table.create()
  File "C:\Program Files\python37\lib\site-packages\pandas\io\sql.py", line 856, in create
    if self.exists():
  File "C:\Program Files\python37\lib\site-packages\pandas\io\sql.py", line 840, in exists
    return self.pd_sql.has_table(self.name, self.schema)
  File "C:\Program Files\python37\lib\site-packages\pandas\io\sql.py", line 1787, in has_table
    self.connectable.dialect.has_table, name, schema or self.meta.schema
  File "C:\Program Files\python37\lib\site-packages\sqlalchemy\engine\base.py", line 2211, in run_callable
    with self._contextual_connect() as conn:
  File "C:\Program Files\python37\lib\site-packages\sqlalchemy\engine\base.py", line 2302, in _contextual_connect
    self._wrap_pool_connect(self.pool.connect, None),
  File "C:\Program Files\python37\lib\site-packages\sqlalchemy\engine\base.py", line 2340, in _wrap_pool_connect
    e, dialect, self
  File "C:\Program Files\python37\lib\site-packages\sqlalchemy\engine\base.py", line 1584, in _handle_dbapi_exception_noconnection
    sqlalchemy_exception, with_traceback=exc_info[2], from_=e
  File "C:\Program Files\python37\lib\site-packages\sqlalchemy\util\compat.py", line 182, in raise_
    raise exception
  File "C:\Program Files\python37\lib\site-packages\sqlalchemy\engine\base.py", line 2336, in _wrap_pool_connect
    return fn()
  File "C:\Program Files\python37\lib\site-packages\sqlalchemy\pool\base.py", line 364, in connect
    return _ConnectionFairy._checkout(self)
  File "C:\Program Files\python37\lib\site-packages\sqlalchemy\pool\base.py", line 778, in _checkout
    fairy = _ConnectionRecord.checkout(pool)
  File "C:\Program Files\python37\lib\site-packages\sqlalchemy\pool\base.py", line 495, in checkout
    rec = pool._do_get()
  File "C:\Program Files\python37\lib\site-packages\sqlalchemy\pool\impl.py", line 140, in _do_get
    self._dec_overflow()
  File "C:\Program Files\python37\lib\site-packages\sqlalchemy\util\langhelpers.py", line 70, in __exit__
    with_traceback=exc_tb,
  File "C:\Program Files\python37\lib\site-packages\sqlalchemy\util\compat.py", line 182, in raise_
    raise exception
  File "C:\Program Files\python37\lib\site-packages\sqlalchemy\pool\impl.py", line 137, in _do_get
    return self._create_connection()
  File "C:\Program Files\python37\lib\site-packages\sqlalchemy\pool\base.py", line 309, in _create_connection
    return _ConnectionRecord(self)
  File "C:\Program Files\python37\lib\site-packages\sqlalchemy\pool\base.py", line 440, in __init__
    self.__connect(first_connect_check=True)
  File "C:\Program Files\python37\lib\site-packages\sqlalchemy\pool\base.py", line 661, in __connect
    pool.logger.debug("Error on connect(): %s", e)
  File "C:\Program Files\python37\lib\site-packages\sqlalchemy\util\langhelpers.py", line 70, in __exit__
    with_traceback=exc_tb,
  File "C:\Program Files\python37\lib\site-packages\sqlalchemy\util\compat.py", line 182, in raise_
    raise exception
  File "C:\Program Files\python37\lib\site-packages\sqlalchemy\pool\base.py", line 656, in __connect
    connection = pool._invoke_creator(self)
  File "C:\Program Files\python37\lib\site-packages\sqlalchemy\engine\strategies.py", line 114, in connect
    return dialect.connect(*cargs, **cparams)
  File "C:\Program Files\python37\lib\site-packages\sqlalchemy\engine\default.py", line 493, in connect
    return self.dbapi.connect(*cargs, **cparams)
  File "C:\Program Files\python37\lib\site-packages\pymysql\__init__.py", line 94, in Connect
    return Connection(*args, **kwargs)
  File "C:\Program Files\python37\lib\site-packages\pymysql\connections.py", line 327, in __init__
    self.connect()
  File "C:\Program Files\python37\lib\site-packages\pymysql\connections.py", line 619, in connect
    raise exc
sqlalchemy.exc.OperationalError: (pymysql.err.OperationalError) (2003, "Can't connect to MySQL server on 'qq532978773.f3322.net' ([Errno 11001] getaddrinfo failed)")
(Background on this error at: http://sqlalche.me/e/13/e3q8)

2021-07-08 00:31:37,877 root  INFO   49 17728 Thread-1 15888 C:\Users\OneDrive - ncist.edu.cn\project\mystock\data\akshare\yjbb.py update_yjbb_to_db start
2021-07-08 00:31:38,079 root  ERROR   54 17728 Thread-1 15888 C:\Users\OneDrive - ncist.edu.cn\project\mystock\data\akshare\yjbb.py update_yjbb_to_db error
2021-07-08 00:31:38,080 root  ERROR   55 17728 Thread-1 15888 Traceback (most recent call last):
  File "C:\Program Files\python37\lib\site-packages\pymysql\connections.py", line 571, in connect
    **kwargs)
  File "C:\Program Files\python37\lib\socket.py", line 707, in create_connection
    for res in getaddrinfo(host, port, 0, SOCK_STREAM):
  File "C:\Program Files\python37\lib\socket.py", line 752, in getaddrinfo
    for res in _socket.getaddrinfo(host, port, family, type, proto, flags):
socket.gaierror: [Errno 11001] getaddrinfo failed

During handling of the above exception, another exception occurred:

Traceback (most recent call last):
  File "C:\Program Files\python37\lib\site-packages\sqlalchemy\engine\base.py", line 2336, in _wrap_pool_connect
    return fn()
  File "C:\Program Files\python37\lib\site-packages\sqlalchemy\pool\base.py", line 364, in connect
    return _ConnectionFairy._checkout(self)
  File "C:\Program Files\python37\lib\site-packages\sqlalchemy\pool\base.py", line 778, in _checkout
    fairy = _ConnectionRecord.checkout(pool)
  File "C:\Program Files\python37\lib\site-packages\sqlalchemy\pool\base.py", line 495, in checkout
    rec = pool._do_get()
  File "C:\Program Files\python37\lib\site-packages\sqlalchemy\pool\impl.py", line 140, in _do_get
    self._dec_overflow()
  File "C:\Program Files\python37\lib\site-packages\sqlalchemy\util\langhelpers.py", line 70, in __exit__
    with_traceback=exc_tb,
  File "C:\Program Files\python37\lib\site-packages\sqlalchemy\util\compat.py", line 182, in raise_
    raise exception
  File "C:\Program Files\python37\lib\site-packages\sqlalchemy\pool\impl.py", line 137, in _do_get
    return self._create_connection()
  File "C:\Program Files\python37\lib\site-packages\sqlalchemy\pool\base.py", line 309, in _create_connection
    return _ConnectionRecord(self)
  File "C:\Program Files\python37\lib\site-packages\sqlalchemy\pool\base.py", line 440, in __init__
    self.__connect(first_connect_check=True)
  File "C:\Program Files\python37\lib\site-packages\sqlalchemy\pool\base.py", line 661, in __connect
    pool.logger.debug("Error on connect(): %s", e)
  File "C:\Program Files\python37\lib\site-packages\sqlalchemy\util\langhelpers.py", line 70, in __exit__
    with_traceback=exc_tb,
  File "C:\Program Files\python37\lib\site-packages\sqlalchemy\util\compat.py", line 182, in raise_
    raise exception
  File "C:\Program Files\python37\lib\site-packages\sqlalchemy\pool\base.py", line 656, in __connect
    connection = pool._invoke_creator(self)
  File "C:\Program Files\python37\lib\site-packages\sqlalchemy\engine\strategies.py", line 114, in connect
    return dialect.connect(*cargs, **cparams)
  File "C:\Program Files\python37\lib\site-packages\sqlalchemy\engine\default.py", line 493, in connect
    return self.dbapi.connect(*cargs, **cparams)
  File "C:\Program Files\python37\lib\site-packages\pymysql\__init__.py", line 94, in Connect
    return Connection(*args, **kwargs)
  File "C:\Program Files\python37\lib\site-packages\pymysql\connections.py", line 327, in __init__
    self.connect()
  File "C:\Program Files\python37\lib\site-packages\pymysql\connections.py", line 619, in connect
    raise exc
pymysql.err.OperationalError: (2003, "Can't connect to MySQL server on 'qq532978773.f3322.net' ([Errno 11001] getaddrinfo failed)")

The above exception was the direct cause of the following exception:

Traceback (most recent call last):
  File "C:\Users\OneDrive - ncist.edu.cn\project\mystock\logger\my_logger.py", line 50, in wrapped_function
    res=func(*args, **kwargs)
  File "C:\Users\OneDrive - ncist.edu.cn\project\mystock\data\akshare\yjbb.py", line 109, in update_yjbb_to_db
    timeUtil.saveOperationTime(tablename)
  File "C:\Users\OneDrive - ncist.edu.cn\project\mystock\utils\timeUtil.py", line 29, in saveOperationTime
    operation.to_sql(name='tb_operation_time',con=con,if_exists='append',index=False)
  File "C:\Program Files\python37\lib\site-packages\pandas\core\generic.py", line 2879, in to_sql
    method=method,
  File "C:\Program Files\python37\lib\site-packages\pandas\io\sql.py", line 728, in to_sql
    **engine_kwargs,
  File "C:\Program Files\python37\lib\site-packages\pandas\io\sql.py", line 1758, in to_sql
    dtype=dtype,
  File "C:\Program Files\python37\lib\site-packages\pandas\io\sql.py", line 1650, in prep_table
    table.create()
  File "C:\Program Files\python37\lib\site-packages\pandas\io\sql.py", line 856, in create
    if self.exists():
  File "C:\Program Files\python37\lib\site-packages\pandas\io\sql.py", line 840, in exists
    return self.pd_sql.has_table(self.name, self.schema)
  File "C:\Program Files\python37\lib\site-packages\pandas\io\sql.py", line 1787, in has_table
    self.connectable.dialect.has_table, name, schema or self.meta.schema
  File "C:\Program Files\python37\lib\site-packages\sqlalchemy\engine\base.py", line 2211, in run_callable
    with self._contextual_connect() as conn:
  File "C:\Program Files\python37\lib\site-packages\sqlalchemy\engine\base.py", line 2302, in _contextual_connect
    self._wrap_pool_connect(self.pool.connect, None),
  File "C:\Program Files\python37\lib\site-packages\sqlalchemy\engine\base.py", line 2340, in _wrap_pool_connect
    e, dialect, self
  File "C:\Program Files\python37\lib\site-packages\sqlalchemy\engine\base.py", line 1584, in _handle_dbapi_exception_noconnection
    sqlalchemy_exception, with_traceback=exc_info[2], from_=e
  File "C:\Program Files\python37\lib\site-packages\sqlalchemy\util\compat.py", line 182, in raise_
    raise exception
  File "C:\Program Files\python37\lib\site-packages\sqlalchemy\engine\base.py", line 2336, in _wrap_pool_connect
    return fn()
  File "C:\Program Files\python37\lib\site-packages\sqlalchemy\pool\base.py", line 364, in connect
    return _ConnectionFairy._checkout(self)
  File "C:\Program Files\python37\lib\site-packages\sqlalchemy\pool\base.py", line 778, in _checkout
    fairy = _ConnectionRecord.checkout(pool)
  File "C:\Program Files\python37\lib\site-packages\sqlalchemy\pool\base.py", line 495, in checkout
    rec = pool._do_get()
  File "C:\Program Files\python37\lib\site-packages\sqlalchemy\pool\impl.py", line 140, in _do_get
    self._dec_overflow()
  File "C:\Program Files\python37\lib\site-packages\sqlalchemy\util\langhelpers.py", line 70, in __exit__
    with_traceback=exc_tb,
  File "C:\Program Files\python37\lib\site-packages\sqlalchemy\util\compat.py", line 182, in raise_
    raise exception
  File "C:\Program Files\python37\lib\site-packages\sqlalchemy\pool\impl.py", line 137, in _do_get
    return self._create_connection()
  File "C:\Program Files\python37\lib\site-packages\sqlalchemy\pool\base.py", line 309, in _create_connection
    return _ConnectionRecord(self)
  File "C:\Program Files\python37\lib\site-packages\sqlalchemy\pool\base.py", line 440, in __init__
    self.__connect(first_connect_check=True)
  File "C:\Program Files\python37\lib\site-packages\sqlalchemy\pool\base.py", line 661, in __connect
    pool.logger.debug("Error on connect(): %s", e)
  File "C:\Program Files\python37\lib\site-packages\sqlalchemy\util\langhelpers.py", line 70, in __exit__
    with_traceback=exc_tb,
  File "C:\Program Files\python37\lib\site-packages\sqlalchemy\util\compat.py", line 182, in raise_
    raise exception
  File "C:\Program Files\python37\lib\site-packages\sqlalchemy\pool\base.py", line 656, in __connect
    connection = pool._invoke_creator(self)
  File "C:\Program Files\python37\lib\site-packages\sqlalchemy\engine\strategies.py", line 114, in connect
    return dialect.connect(*cargs, **cparams)
  File "C:\Program Files\python37\lib\site-packages\sqlalchemy\engine\default.py", line 493, in connect
    return self.dbapi.connect(*cargs, **cparams)
  File "C:\Program Files\python37\lib\site-packages\pymysql\__init__.py", line 94, in Connect
    return Connection(*args, **kwargs)
  File "C:\Program Files\python37\lib\site-packages\pymysql\connections.py", line 327, in __init__
    self.connect()
  File "C:\Program Files\python37\lib\site-packages\pymysql\connections.py", line 619, in connect
    raise exc
sqlalchemy.exc.OperationalError: (pymysql.err.OperationalError) (2003, "Can't connect to MySQL server on 'qq532978773.f3322.net' ([Errno 11001] getaddrinfo failed)")
(Background on this error at: http://sqlalche.me/e/13/e3q8)

2021-07-08 00:31:38,081 root  INFO   49 17728 Thread-1 15888 C:\Users\OneDrive - ncist.edu.cn\project\mystock\data\akshare\yjbb.py update_yjbb_to_db start
2021-07-08 00:31:38,275 root  ERROR   54 17728 Thread-1 15888 C:\Users\OneDrive - ncist.edu.cn\project\mystock\data\akshare\yjbb.py update_yjbb_to_db error
2021-07-08 00:31:38,276 root  ERROR   55 17728 Thread-1 15888 Traceback (most recent call last):
  File "C:\Program Files\python37\lib\site-packages\pymysql\connections.py", line 571, in connect
    **kwargs)
  File "C:\Program Files\python37\lib\socket.py", line 707, in create_connection
    for res in getaddrinfo(host, port, 0, SOCK_STREAM):
  File "C:\Program Files\python37\lib\socket.py", line 752, in getaddrinfo
    for res in _socket.getaddrinfo(host, port, family, type, proto, flags):
socket.gaierror: [Errno 11001] getaddrinfo failed

During handling of the above exception, another exception occurred:

Traceback (most recent call last):
  File "C:\Program Files\python37\lib\site-packages\sqlalchemy\engine\base.py", line 2336, in _wrap_pool_connect
    return fn()
  File "C:\Program Files\python37\lib\site-packages\sqlalchemy\pool\base.py", line 364, in connect
    return _ConnectionFairy._checkout(self)
  File "C:\Program Files\python37\lib\site-packages\sqlalchemy\pool\base.py", line 778, in _checkout
    fairy = _ConnectionRecord.checkout(pool)
  File "C:\Program Files\python37\lib\site-packages\sqlalchemy\pool\base.py", line 495, in checkout
    rec = pool._do_get()
  File "C:\Program Files\python37\lib\site-packages\sqlalchemy\pool\impl.py", line 140, in _do_get
    self._dec_overflow()
  File "C:\Program Files\python37\lib\site-packages\sqlalchemy\util\langhelpers.py", line 70, in __exit__
    with_traceback=exc_tb,
  File "C:\Program Files\python37\lib\site-packages\sqlalchemy\util\compat.py", line 182, in raise_
    raise exception
  File "C:\Program Files\python37\lib\site-packages\sqlalchemy\pool\impl.py", line 137, in _do_get
    return self._create_connection()
  File "C:\Program Files\python37\lib\site-packages\sqlalchemy\pool\base.py", line 309, in _create_connection
    return _ConnectionRecord(self)
  File "C:\Program Files\python37\lib\site-packages\sqlalchemy\pool\base.py", line 440, in __init__
    self.__connect(first_connect_check=True)
  File "C:\Program Files\python37\lib\site-packages\sqlalchemy\pool\base.py", line 661, in __connect
    pool.logger.debug("Error on connect(): %s", e)
  File "C:\Program Files\python37\lib\site-packages\sqlalchemy\util\langhelpers.py", line 70, in __exit__
    with_traceback=exc_tb,
  File "C:\Program Files\python37\lib\site-packages\sqlalchemy\util\compat.py", line 182, in raise_
    raise exception
  File "C:\Program Files\python37\lib\site-packages\sqlalchemy\pool\base.py", line 656, in __connect
    connection = pool._invoke_creator(self)
  File "C:\Program Files\python37\lib\site-packages\sqlalchemy\engine\strategies.py", line 114, in connect
    return dialect.connect(*cargs, **cparams)
  File "C:\Program Files\python37\lib\site-packages\sqlalchemy\engine\default.py", line 493, in connect
    return self.dbapi.connect(*cargs, **cparams)
  File "C:\Program Files\python37\lib\site-packages\pymysql\__init__.py", line 94, in Connect
    return Connection(*args, **kwargs)
  File "C:\Program Files\python37\lib\site-packages\pymysql\connections.py", line 327, in __init__
    self.connect()
  File "C:\Program Files\python37\lib\site-packages\pymysql\connections.py", line 619, in connect
    raise exc
pymysql.err.OperationalError: (2003, "Can't connect to MySQL server on 'qq532978773.f3322.net' ([Errno 11001] getaddrinfo failed)")

The above exception was the direct cause of the following exception:

Traceback (most recent call last):
  File "C:\Users\OneDrive - ncist.edu.cn\project\mystock\logger\my_logger.py", line 50, in wrapped_function
    res=func(*args, **kwargs)
  File "C:\Users\OneDrive - ncist.edu.cn\project\mystock\data\akshare\yjbb.py", line 109, in update_yjbb_to_db
    timeUtil.saveOperationTime(tablename)
  File "C:\Users\OneDrive - ncist.edu.cn\project\mystock\utils\timeUtil.py", line 29, in saveOperationTime
    operation.to_sql(name='tb_operation_time',con=con,if_exists='append',index=False)
  File "C:\Program Files\python37\lib\site-packages\pandas\core\generic.py", line 2879, in to_sql
    method=method,
  File "C:\Program Files\python37\lib\site-packages\pandas\io\sql.py", line 728, in to_sql
    **engine_kwargs,
  File "C:\Program Files\python37\lib\site-packages\pandas\io\sql.py", line 1758, in to_sql
    dtype=dtype,
  File "C:\Program Files\python37\lib\site-packages\pandas\io\sql.py", line 1650, in prep_table
    table.create()
  File "C:\Program Files\python37\lib\site-packages\pandas\io\sql.py", line 856, in create
    if self.exists():
  File "C:\Program Files\python37\lib\site-packages\pandas\io\sql.py", line 840, in exists
    return self.pd_sql.has_table(self.name, self.schema)
  File "C:\Program Files\python37\lib\site-packages\pandas\io\sql.py", line 1787, in has_table
    self.connectable.dialect.has_table, name, schema or self.meta.schema
  File "C:\Program Files\python37\lib\site-packages\sqlalchemy\engine\base.py", line 2211, in run_callable
    with self._contextual_connect() as conn:
  File "C:\Program Files\python37\lib\site-packages\sqlalchemy\engine\base.py", line 2302, in _contextual_connect
    self._wrap_pool_connect(self.pool.connect, None),
  File "C:\Program Files\python37\lib\site-packages\sqlalchemy\engine\base.py", line 2340, in _wrap_pool_connect
    e, dialect, self
  File "C:\Program Files\python37\lib\site-packages\sqlalchemy\engine\base.py", line 1584, in _handle_dbapi_exception_noconnection
    sqlalchemy_exception, with_traceback=exc_info[2], from_=e
  File "C:\Program Files\python37\lib\site-packages\sqlalchemy\util\compat.py", line 182, in raise_
    raise exception
  File "C:\Program Files\python37\lib\site-packages\sqlalchemy\engine\base.py", line 2336, in _wrap_pool_connect
    return fn()
  File "C:\Program Files\python37\lib\site-packages\sqlalchemy\pool\base.py", line 364, in connect
    return _ConnectionFairy._checkout(self)
  File "C:\Program Files\python37\lib\site-packages\sqlalchemy\pool\base.py", line 778, in _checkout
    fairy = _ConnectionRecord.checkout(pool)
  File "C:\Program Files\python37\lib\site-packages\sqlalchemy\pool\base.py", line 495, in checkout
    rec = pool._do_get()
  File "C:\Program Files\python37\lib\site-packages\sqlalchemy\pool\impl.py", line 140, in _do_get
    self._dec_overflow()
  File "C:\Program Files\python37\lib\site-packages\sqlalchemy\util\langhelpers.py", line 70, in __exit__
    with_traceback=exc_tb,
  File "C:\Program Files\python37\lib\site-packages\sqlalchemy\util\compat.py", line 182, in raise_
    raise exception
  File "C:\Program Files\python37\lib\site-packages\sqlalchemy\pool\impl.py", line 137, in _do_get
    return self._create_connection()
  File "C:\Program Files\python37\lib\site-packages\sqlalchemy\pool\base.py", line 309, in _create_connection
    return _ConnectionRecord(self)
  File "C:\Program Files\python37\lib\site-packages\sqlalchemy\pool\base.py", line 440, in __init__
    self.__connect(first_connect_check=True)
  File "C:\Program Files\python37\lib\site-packages\sqlalchemy\pool\base.py", line 661, in __connect
    pool.logger.debug("Error on connect(): %s", e)
  File "C:\Program Files\python37\lib\site-packages\sqlalchemy\util\langhelpers.py", line 70, in __exit__
    with_traceback=exc_tb,
  File "C:\Program Files\python37\lib\site-packages\sqlalchemy\util\compat.py", line 182, in raise_
    raise exception
  File "C:\Program Files\python37\lib\site-packages\sqlalchemy\pool\base.py", line 656, in __connect
    connection = pool._invoke_creator(self)
  File "C:\Program Files\python37\lib\site-packages\sqlalchemy\engine\strategies.py", line 114, in connect
    return dialect.connect(*cargs, **cparams)
  File "C:\Program Files\python37\lib\site-packages\sqlalchemy\engine\default.py", line 493, in connect
    return self.dbapi.connect(*cargs, **cparams)
  File "C:\Program Files\python37\lib\site-packages\pymysql\__init__.py", line 94, in Connect
    return Connection(*args, **kwargs)
  File "C:\Program Files\python37\lib\site-packages\pymysql\connections.py", line 327, in __init__
    self.connect()
  File "C:\Program Files\python37\lib\site-packages\pymysql\connections.py", line 619, in connect
    raise exc
sqlalchemy.exc.OperationalError: (pymysql.err.OperationalError) (2003, "Can't connect to MySQL server on 'qq532978773.f3322.net' ([Errno 11001] getaddrinfo failed)")
(Background on this error at: http://sqlalche.me/e/13/e3q8)

2021-07-08 00:31:38,276 root  INFO   49 17728 Thread-1 15888 C:\Users\OneDrive - ncist.edu.cn\project\mystock\data\akshare\yjbb.py update_yjbb_to_db start
2021-07-08 00:31:38,468 root  ERROR   54 17728 Thread-1 15888 C:\Users\OneDrive - ncist.edu.cn\project\mystock\data\akshare\yjbb.py update_yjbb_to_db error
2021-07-08 00:31:38,468 root  ERROR   55 17728 Thread-1 15888 Traceback (most recent call last):
  File "C:\Program Files\python37\lib\site-packages\pymysql\connections.py", line 571, in connect
    **kwargs)
  File "C:\Program Files\python37\lib\socket.py", line 707, in create_connection
    for res in getaddrinfo(host, port, 0, SOCK_STREAM):
  File "C:\Program Files\python37\lib\socket.py", line 752, in getaddrinfo
    for res in _socket.getaddrinfo(host, port, family, type, proto, flags):
socket.gaierror: [Errno 11001] getaddrinfo failed

During handling of the above exception, another exception occurred:

Traceback (most recent call last):
  File "C:\Program Files\python37\lib\site-packages\sqlalchemy\engine\base.py", line 2336, in _wrap_pool_connect
    return fn()
  File "C:\Program Files\python37\lib\site-packages\sqlalchemy\pool\base.py", line 364, in connect
    return _ConnectionFairy._checkout(self)
  File "C:\Program Files\python37\lib\site-packages\sqlalchemy\pool\base.py", line 778, in _checkout
    fairy = _ConnectionRecord.checkout(pool)
  File "C:\Program Files\python37\lib\site-packages\sqlalchemy\pool\base.py", line 495, in checkout
    rec = pool._do_get()
  File "C:\Program Files\python37\lib\site-packages\sqlalchemy\pool\impl.py", line 140, in _do_get
    self._dec_overflow()
  File "C:\Program Files\python37\lib\site-packages\sqlalchemy\util\langhelpers.py", line 70, in __exit__
    with_traceback=exc_tb,
  File "C:\Program Files\python37\lib\site-packages\sqlalchemy\util\compat.py", line 182, in raise_
    raise exception
  File "C:\Program Files\python37\lib\site-packages\sqlalchemy\pool\impl.py", line 137, in _do_get
    return self._create_connection()
  File "C:\Program Files\python37\lib\site-packages\sqlalchemy\pool\base.py", line 309, in _create_connection
    return _ConnectionRecord(self)
  File "C:\Program Files\python37\lib\site-packages\sqlalchemy\pool\base.py", line 440, in __init__
    self.__connect(first_connect_check=True)
  File "C:\Program Files\python37\lib\site-packages\sqlalchemy\pool\base.py", line 661, in __connect
    pool.logger.debug("Error on connect(): %s", e)
  File "C:\Program Files\python37\lib\site-packages\sqlalchemy\util\langhelpers.py", line 70, in __exit__
    with_traceback=exc_tb,
  File "C:\Program Files\python37\lib\site-packages\sqlalchemy\util\compat.py", line 182, in raise_
    raise exception
  File "C:\Program Files\python37\lib\site-packages\sqlalchemy\pool\base.py", line 656, in __connect
    connection = pool._invoke_creator(self)
  File "C:\Program Files\python37\lib\site-packages\sqlalchemy\engine\strategies.py", line 114, in connect
    return dialect.connect(*cargs, **cparams)
  File "C:\Program Files\python37\lib\site-packages\sqlalchemy\engine\default.py", line 493, in connect
    return self.dbapi.connect(*cargs, **cparams)
  File "C:\Program Files\python37\lib\site-packages\pymysql\__init__.py", line 94, in Connect
    return Connection(*args, **kwargs)
  File "C:\Program Files\python37\lib\site-packages\pymysql\connections.py", line 327, in __init__
    self.connect()
  File "C:\Program Files\python37\lib\site-packages\pymysql\connections.py", line 619, in connect
    raise exc
pymysql.err.OperationalError: (2003, "Can't connect to MySQL server on 'qq532978773.f3322.net' ([Errno 11001] getaddrinfo failed)")

The above exception was the direct cause of the following exception:

Traceback (most recent call last):
  File "C:\Users\OneDrive - ncist.edu.cn\project\mystock\logger\my_logger.py", line 50, in wrapped_function
    res=func(*args, **kwargs)
  File "C:\Users\OneDrive - ncist.edu.cn\project\mystock\data\akshare\yjbb.py", line 109, in update_yjbb_to_db
    timeUtil.saveOperationTime(tablename)
  File "C:\Users\OneDrive - ncist.edu.cn\project\mystock\utils\timeUtil.py", line 29, in saveOperationTime
    operation.to_sql(name='tb_operation_time',con=con,if_exists='append',index=False)
  File "C:\Program Files\python37\lib\site-packages\pandas\core\generic.py", line 2879, in to_sql
    method=method,
  File "C:\Program Files\python37\lib\site-packages\pandas\io\sql.py", line 728, in to_sql
    **engine_kwargs,
  File "C:\Program Files\python37\lib\site-packages\pandas\io\sql.py", line 1758, in to_sql
    dtype=dtype,
  File "C:\Program Files\python37\lib\site-packages\pandas\io\sql.py", line 1650, in prep_table
    table.create()
  File "C:\Program Files\python37\lib\site-packages\pandas\io\sql.py", line 856, in create
    if self.exists():
  File "C:\Program Files\python37\lib\site-packages\pandas\io\sql.py", line 840, in exists
    return self.pd_sql.has_table(self.name, self.schema)
  File "C:\Program Files\python37\lib\site-packages\pandas\io\sql.py", line 1787, in has_table
    self.connectable.dialect.has_table, name, schema or self.meta.schema
  File "C:\Program Files\python37\lib\site-packages\sqlalchemy\engine\base.py", line 2211, in run_callable
    with self._contextual_connect() as conn:
  File "C:\Program Files\python37\lib\site-packages\sqlalchemy\engine\base.py", line 2302, in _contextual_connect
    self._wrap_pool_connect(self.pool.connect, None),
  File "C:\Program Files\python37\lib\site-packages\sqlalchemy\engine\base.py", line 2340, in _wrap_pool_connect
    e, dialect, self
  File "C:\Program Files\python37\lib\site-packages\sqlalchemy\engine\base.py", line 1584, in _handle_dbapi_exception_noconnection
    sqlalchemy_exception, with_traceback=exc_info[2], from_=e
  File "C:\Program Files\python37\lib\site-packages\sqlalchemy\util\compat.py", line 182, in raise_
    raise exception
  File "C:\Program Files\python37\lib\site-packages\sqlalchemy\engine\base.py", line 2336, in _wrap_pool_connect
    return fn()
  File "C:\Program Files\python37\lib\site-packages\sqlalchemy\pool\base.py", line 364, in connect
    return _ConnectionFairy._checkout(self)
  File "C:\Program Files\python37\lib\site-packages\sqlalchemy\pool\base.py", line 778, in _checkout
    fairy = _ConnectionRecord.checkout(pool)
  File "C:\Program Files\python37\lib\site-packages\sqlalchemy\pool\base.py", line 495, in checkout
    rec = pool._do_get()
  File "C:\Program Files\python37\lib\site-packages\sqlalchemy\pool\impl.py", line 140, in _do_get
    self._dec_overflow()
  File "C:\Program Files\python37\lib\site-packages\sqlalchemy\util\langhelpers.py", line 70, in __exit__
    with_traceback=exc_tb,
  File "C:\Program Files\python37\lib\site-packages\sqlalchemy\util\compat.py", line 182, in raise_
    raise exception
  File "C:\Program Files\python37\lib\site-packages\sqlalchemy\pool\impl.py", line 137, in _do_get
    return self._create_connection()
  File "C:\Program Files\python37\lib\site-packages\sqlalchemy\pool\base.py", line 309, in _create_connection
    return _ConnectionRecord(self)
  File "C:\Program Files\python37\lib\site-packages\sqlalchemy\pool\base.py", line 440, in __init__
    self.__connect(first_connect_check=True)
  File "C:\Program Files\python37\lib\site-packages\sqlalchemy\pool\base.py", line 661, in __connect
    pool.logger.debug("Error on connect(): %s", e)
  File "C:\Program Files\python37\lib\site-packages\sqlalchemy\util\langhelpers.py", line 70, in __exit__
    with_traceback=exc_tb,
  File "C:\Program Files\python37\lib\site-packages\sqlalchemy\util\compat.py", line 182, in raise_
    raise exception
  File "C:\Program Files\python37\lib\site-packages\sqlalchemy\pool\base.py", line 656, in __connect
    connection = pool._invoke_creator(self)
  File "C:\Program Files\python37\lib\site-packages\sqlalchemy\engine\strategies.py", line 114, in connect
    return dialect.connect(*cargs, **cparams)
  File "C:\Program Files\python37\lib\site-packages\sqlalchemy\engine\default.py", line 493, in connect
    return self.dbapi.connect(*cargs, **cparams)
  File "C:\Program Files\python37\lib\site-packages\pymysql\__init__.py", line 94, in Connect
    return Connection(*args, **kwargs)
  File "C:\Program Files\python37\lib\site-packages\pymysql\connections.py", line 327, in __init__
    self.connect()
  File "C:\Program Files\python37\lib\site-packages\pymysql\connections.py", line 619, in connect
    raise exc
sqlalchemy.exc.OperationalError: (pymysql.err.OperationalError) (2003, "Can't connect to MySQL server on 'qq532978773.f3322.net' ([Errno 11001] getaddrinfo failed)")
(Background on this error at: http://sqlalche.me/e/13/e3q8)

2021-07-08 00:31:38,469 root  INFO   49 17728 Thread-1 15888 C:\Users\OneDrive - ncist.edu.cn\project\mystock\data\akshare\yjbb.py update_yjbb_to_db start
2021-07-08 00:31:38,662 root  ERROR   54 17728 Thread-1 15888 C:\Users\OneDrive - ncist.edu.cn\project\mystock\data\akshare\yjbb.py update_yjbb_to_db error
2021-07-08 00:31:38,662 root  ERROR   55 17728 Thread-1 15888 Traceback (most recent call last):
  File "C:\Program Files\python37\lib\site-packages\pymysql\connections.py", line 571, in connect
    **kwargs)
  File "C:\Program Files\python37\lib\socket.py", line 707, in create_connection
    for res in getaddrinfo(host, port, 0, SOCK_STREAM):
  File "C:\Program Files\python37\lib\socket.py", line 752, in getaddrinfo
    for res in _socket.getaddrinfo(host, port, family, type, proto, flags):
socket.gaierror: [Errno 11001] getaddrinfo failed

During handling of the above exception, another exception occurred:

Traceback (most recent call last):
  File "C:\Program Files\python37\lib\site-packages\sqlalchemy\engine\base.py", line 2336, in _wrap_pool_connect
    return fn()
  File "C:\Program Files\python37\lib\site-packages\sqlalchemy\pool\base.py", line 364, in connect
    return _ConnectionFairy._checkout(self)
  File "C:\Program Files\python37\lib\site-packages\sqlalchemy\pool\base.py", line 778, in _checkout
    fairy = _ConnectionRecord.checkout(pool)
  File "C:\Program Files\python37\lib\site-packages\sqlalchemy\pool\base.py", line 495, in checkout
    rec = pool._do_get()
  File "C:\Program Files\python37\lib\site-packages\sqlalchemy\pool\impl.py", line 140, in _do_get
    self._dec_overflow()
  File "C:\Program Files\python37\lib\site-packages\sqlalchemy\util\langhelpers.py", line 70, in __exit__
    with_traceback=exc_tb,
  File "C:\Program Files\python37\lib\site-packages\sqlalchemy\util\compat.py", line 182, in raise_
    raise exception
  File "C:\Program Files\python37\lib\site-packages\sqlalchemy\pool\impl.py", line 137, in _do_get
    return self._create_connection()
  File "C:\Program Files\python37\lib\site-packages\sqlalchemy\pool\base.py", line 309, in _create_connection
    return _ConnectionRecord(self)
  File "C:\Program Files\python37\lib\site-packages\sqlalchemy\pool\base.py", line 440, in __init__
    self.__connect(first_connect_check=True)
  File "C:\Program Files\python37\lib\site-packages\sqlalchemy\pool\base.py", line 661, in __connect
    pool.logger.debug("Error on connect(): %s", e)
  File "C:\Program Files\python37\lib\site-packages\sqlalchemy\util\langhelpers.py", line 70, in __exit__
    with_traceback=exc_tb,
  File "C:\Program Files\python37\lib\site-packages\sqlalchemy\util\compat.py", line 182, in raise_
    raise exception
  File "C:\Program Files\python37\lib\site-packages\sqlalchemy\pool\base.py", line 656, in __connect
    connection = pool._invoke_creator(self)
  File "C:\Program Files\python37\lib\site-packages\sqlalchemy\engine\strategies.py", line 114, in connect
    return dialect.connect(*cargs, **cparams)
  File "C:\Program Files\python37\lib\site-packages\sqlalchemy\engine\default.py", line 493, in connect
    return self.dbapi.connect(*cargs, **cparams)
  File "C:\Program Files\python37\lib\site-packages\pymysql\__init__.py", line 94, in Connect
    return Connection(*args, **kwargs)
  File "C:\Program Files\python37\lib\site-packages\pymysql\connections.py", line 327, in __init__
    self.connect()
  File "C:\Program Files\python37\lib\site-packages\pymysql\connections.py", line 619, in connect
    raise exc
pymysql.err.OperationalError: (2003, "Can't connect to MySQL server on 'qq532978773.f3322.net' ([Errno 11001] getaddrinfo failed)")

The above exception was the direct cause of the following exception:

Traceback (most recent call last):
  File "C:\Users\OneDrive - ncist.edu.cn\project\mystock\logger\my_logger.py", line 50, in wrapped_function
    res=func(*args, **kwargs)
  File "C:\Users\OneDrive - ncist.edu.cn\project\mystock\data\akshare\yjbb.py", line 109, in update_yjbb_to_db
    timeUtil.saveOperationTime(tablename)
  File "C:\Users\OneDrive - ncist.edu.cn\project\mystock\utils\timeUtil.py", line 29, in saveOperationTime
    operation.to_sql(name='tb_operation_time',con=con,if_exists='append',index=False)
  File "C:\Program Files\python37\lib\site-packages\pandas\core\generic.py", line 2879, in to_sql
    method=method,
  File "C:\Program Files\python37\lib\site-packages\pandas\io\sql.py", line 728, in to_sql
    **engine_kwargs,
  File "C:\Program Files\python37\lib\site-packages\pandas\io\sql.py", line 1758, in to_sql
    dtype=dtype,
  File "C:\Program Files\python37\lib\site-packages\pandas\io\sql.py", line 1650, in prep_table
    table.create()
  File "C:\Program Files\python37\lib\site-packages\pandas\io\sql.py", line 856, in create
    if self.exists():
  File "C:\Program Files\python37\lib\site-packages\pandas\io\sql.py", line 840, in exists
    return self.pd_sql.has_table(self.name, self.schema)
  File "C:\Program Files\python37\lib\site-packages\pandas\io\sql.py", line 1787, in has_table
    self.connectable.dialect.has_table, name, schema or self.meta.schema
  File "C:\Program Files\python37\lib\site-packages\sqlalchemy\engine\base.py", line 2211, in run_callable
    with self._contextual_connect() as conn:
  File "C:\Program Files\python37\lib\site-packages\sqlalchemy\engine\base.py", line 2302, in _contextual_connect
    self._wrap_pool_connect(self.pool.connect, None),
  File "C:\Program Files\python37\lib\site-packages\sqlalchemy\engine\base.py", line 2340, in _wrap_pool_connect
    e, dialect, self
  File "C:\Program Files\python37\lib\site-packages\sqlalchemy\engine\base.py", line 1584, in _handle_dbapi_exception_noconnection
    sqlalchemy_exception, with_traceback=exc_info[2], from_=e
  File "C:\Program Files\python37\lib\site-packages\sqlalchemy\util\compat.py", line 182, in raise_
    raise exception
  File "C:\Program Files\python37\lib\site-packages\sqlalchemy\engine\base.py", line 2336, in _wrap_pool_connect
    return fn()
  File "C:\Program Files\python37\lib\site-packages\sqlalchemy\pool\base.py", line 364, in connect
    return _ConnectionFairy._checkout(self)
  File "C:\Program Files\python37\lib\site-packages\sqlalchemy\pool\base.py", line 778, in _checkout
    fairy = _ConnectionRecord.checkout(pool)
  File "C:\Program Files\python37\lib\site-packages\sqlalchemy\pool\base.py", line 495, in checkout
    rec = pool._do_get()
  File "C:\Program Files\python37\lib\site-packages\sqlalchemy\pool\impl.py", line 140, in _do_get
    self._dec_overflow()
  File "C:\Program Files\python37\lib\site-packages\sqlalchemy\util\langhelpers.py", line 70, in __exit__
    with_traceback=exc_tb,
  File "C:\Program Files\python37\lib\site-packages\sqlalchemy\util\compat.py", line 182, in raise_
    raise exception
  File "C:\Program Files\python37\lib\site-packages\sqlalchemy\pool\impl.py", line 137, in _do_get
    return self._create_connection()
  File "C:\Program Files\python37\lib\site-packages\sqlalchemy\pool\base.py", line 309, in _create_connection
    return _ConnectionRecord(self)
  File "C:\Program Files\python37\lib\site-packages\sqlalchemy\pool\base.py", line 440, in __init__
    self.__connect(first_connect_check=True)
  File "C:\Program Files\python37\lib\site-packages\sqlalchemy\pool\base.py", line 661, in __connect
    pool.logger.debug("Error on connect(): %s", e)
  File "C:\Program Files\python37\lib\site-packages\sqlalchemy\util\langhelpers.py", line 70, in __exit__
    with_traceback=exc_tb,
  File "C:\Program Files\python37\lib\site-packages\sqlalchemy\util\compat.py", line 182, in raise_
    raise exception
  File "C:\Program Files\python37\lib\site-packages\sqlalchemy\pool\base.py", line 656, in __connect
    connection = pool._invoke_creator(self)
  File "C:\Program Files\python37\lib\site-packages\sqlalchemy\engine\strategies.py", line 114, in connect
    return dialect.connect(*cargs, **cparams)
  File "C:\Program Files\python37\lib\site-packages\sqlalchemy\engine\default.py", line 493, in connect
    return self.dbapi.connect(*cargs, **cparams)
  File "C:\Program Files\python37\lib\site-packages\pymysql\__init__.py", line 94, in Connect
    return Connection(*args, **kwargs)
  File "C:\Program Files\python37\lib\site-packages\pymysql\connections.py", line 327, in __init__
    self.connect()
  File "C:\Program Files\python37\lib\site-packages\pymysql\connections.py", line 619, in connect
    raise exc
sqlalchemy.exc.OperationalError: (pymysql.err.OperationalError) (2003, "Can't connect to MySQL server on 'qq532978773.f3322.net' ([Errno 11001] getaddrinfo failed)")
(Background on this error at: http://sqlalche.me/e/13/e3q8)

